<?xml version="1.0"?>
<robot name="bowl">
  <link name="world" />

  <link name="bowl">
    <visual>
      <geometry>
	    <mesh filename="package://lock_key/mesh/bowl.STL" scale="0.5 0.5 0.5" />
      </geometry>
    </visual>

    <collision>
      <geometry>
	    <mesh filename="package://lock_key/mesh/bowl.STL" scale="0.5 0.5 0.5"/>
      </geometry>
    </collision>

    <inertial>
      <mass value="0.1" />
      <inertia ixx="0.1" ixy="0.1" ixz="0.1"
	       iyy="0.1" iyz="0.1"
	       izz="0.1" />
    </inertial>
  </link>

  <gazebo reference = "bowl">
<material> Gazebo/Blue</material>
<dampingFactor>0.005</dampingFactor>
<kp>100000000.0</kp>
<kd>1.0</kd>
<mu1>100000.0</mu1>
<mu2>100000.0</mu2>
<maxVel>1.0</maxVel>
<minDepth>10</minDepth>
<turnGravityOff>false</turnGravityOff>
</gazebo>

  <joint name="table_padlock" type="floating">
    <origin rpy="1.57 0 0" xyz="0.1 0.05 0.0" />
    <parent link="world" />
    <child link="bowl" />
  </joint>

</robot>
